Workbook

Sheet Tab 1 Instructions
A1: When not Filled in Entire Workbook is UNCLASSIFIED
A3: Purpose
A4: The purpose of this workbook is for Offerors to provide information required for the Government to efficiently evaluation the Offeror's proposal. Task Order 0001 of the solicitation shall utilize the proposed labor rate pricing for the labor categories included in this workbook.
A5: Additional Tabs can be added to this workbook as needed. Internal equations shall be maintained to allow ease of Government evaluation. All external links must be removed prior to submission.
A6: Instructions and Notes
A7: Tab 2 - IDIQ LCAT Skill Levels and Tab 3 - IDIQ LCAT Descriptions
A8: Offerors shall use the IDIQ LCAT Skill Levels and Descriptions in developing the fully burdened labor rates to be used in responses to Task Order 0001 and all future Task Orders.
A9: Do not alter these tabs.
A10: Tab 4 - IDIQ LCAT Rates
A11: In this tab, Offerors shall enter proposed fully burdened labor rates (FBLRs) for each labor category, skill level, work location and work site combination requested.
A12: Tab 5 - IDIQ and TO1 CLIN Structure
A13: The tab provides an overview of all the CLINs for the IDIQ and the CLIN Structure for Task Order 01 (TO1).
... A20: Do not alter this tab.

Sheet Tab 2 IDIQ LCAT Skill Levels
B2: DO NOT ALTER. DO NOT ADD ADDITIONAL CATEGORIES OR MODIFY EXISTING FIELDS.
B4: The following Labor Category Levels shall be applied to each Labor Category to determine which personnel are appropriate for meeting contract needs, based upon project requirements.
B6: Labor Category Level | C6: Skills & Tasks | D6: Work Level | E6: Guidance Required | F6: Education/Certification/Experience Required
B7: Jr. | C7: Able to follow established processes & checklists | D7: Self-guided individual work | E7: Moderate/Minimal | F7: Bachelor’s degree, Associates degree plus 2 years experience, or a minimum of 4 years of experience, in a related field
C8: Understands & applies basic concepts, ability to use more advanced concepts | D8: Proactive team member | E8: Over time, able to provide guidance & direction to others
C9: Assists senior level technicians, specialists & managers.
B10: Mid. | C10: Able to follow established processes & checklists | D10: Self-guided individual work | E10: Requires guidance only when dealing with new, uncertain, undefined or undeveloped tasks | F10: Bachelor’s degree with at least 3 years’ experience; or Associates degree plus 5 years experience; or a minimum of 8 years of experience in a related IT field
C11: Understands & applies basic concepts, ability to use more advanced concepts | D11: Proactive team member | F11: Over time, able to provide guidance & direction to others
D12: Task lead
B13: Sr. | C13: Able to develop & use more complex concepts & processes: Leads multiple Junior/Mid-level personnel | D13: Self-guided individual work, Key Member of team | E13: Provides expert guidance & direction (possibly as SME) | F13: Has at least 7 years’ experience with a MA/MS or higher degree; or Bachelor’s degree plus 9 years experience; or Associates degree plus 10 years experience; or a minimum of 12 years experience in relevant IT field
C14: Conduct root cause problem analysis Performs multiple tasks at specialist level | D14: Proactive team member, Monitors task(s) | E14: Directs multiple personnel/contractors through entire project life cycle | F14: Applicable software/hardware training & certification (e.g.; specialties such as Amazon Web Services (AWS) cloud developer/engineer, MCSE, etc.)
D15: Task lead, Provides issue resolution | E15: Performs all functional duties independently
C16: Typically works on high-visibility or mission critical aspects of a given program/application
C17: Guide & support Journeyman level personnel
B18: SME | C18: Able to develop & use exceptionally complex concepts & processes that span multiple organizations and disciplines | D18: Leadership | E18: Provides expert guidance & direction | F18: Master’s degree plus 6 years experience; or Bachelor’s degree plus 10 year experience; or Associates degree plus 14 years experience; or a minimum of 16 years experience in relevant IT field
C19: Performs multiple tasks at specialist level | D19: Management | E19: Directs multiple personnel/contractors through entire project life cycle | F19: Applicable software/ hardware/management training & certification (e.g.; specialties like Amazon Web Service architect/engineering, MCSE, etc.)
C20: Guides and Leads multiple Junior/Mid-level personnel | D20: Key member of team | E20: Provides strategic advice, technical guidance and expertise to program and project staff
C21: Recognized as a SME | D21: Oversees or monitors task(s)
C22: Evaluates & recommends new technology & processes based upon cost, risk, mission | D22: Task lead and Provides issue resolution
C23: Typically identified as recognized Industry leaders for a given area of expertise | D23: Initiates, supervises, and/or develops requirements from a project’s inception to conclusion for complex to extremely complex programs
C24: Qualifications and/or particular expertise are exceptional and/or highly unique
C25: Provides detailed analysis, evaluation and recommendations for improvement, optimization development, and/or maintenance efforts for client-specific or mission critical challenges/issues
C26: Consults with client to define need or problem, supervises studies, and leads analyses to collect and analyze data to provide advice and recommend solutions

Sheet Tab 3 IDIQ LCAT Descriptions
B2: DO NOT ALTER. DO NOT ADD ADDITIONAL LABOR CATEGORIES OR MODIFY DESCRIPTIONS.
B4: Labor Category | C4: Description
B5: Program Manager* | C5: • Responsible for the successful cost, schedule, and performance of the contract • Responsible for general oversight and overall execution of the contract providing support and direction to meet targeted outcomes and satisfy the PWS requirements. • Serve as the main point of contact for the Contracting Officer (CO), the Contracting Officer’s Representative (COR), the Government Program Manager, and the Contractor’s senior management • Directly contribute to program efforts in several areas, including cost management/avoidance, schedule estimation and tracking, contract performance management, risk management, requirements analysis, and quality assurance activities • Ensure proper performance of tasks necessary to ensure the most efficient and effective execution of the contract • Utilize expert communication skills needed to direct the skilled technical resources and report on the technical progress, issues, and problem areas, as well as write and review technical documents
B6: Chief Software Architect (CSA)* | C6: • Responsible for the general oversight and overall execution of software development and maintenance utilizing Agile methodologies • Responsible for ensuring the delivery of software to meet targeted outcomes and satisfy the PWS requirements • Facilitate Agile processes, events, and lead process execution and refinement
B7: Chief Systems Engineer (CSE)* | C7: • Responsible for the creation, monitoring, implementation, and documentation of the end-to-end system. • Responsible for the realization of requirements • Creates and reviews new and existing system designs to make recommendations for altering or improving the systems
B8: Information Systems Security Officer (ISSO)* | C8: • Responsible for ensuring that appropriate operational security posture is maintained for an information system and as such, works in close collaboration with the Information System Owner (iSO) • Oversee all work performed by the Information Assurance/Security Specialist personnel
B9: UI / UX Engineer | C9: • Responsible for vision, designing, and creating user interfaces that are visually appealing, easy to use, and intuitive • Collaborates with product managers, application engineers, super-users, and SME's to gather work-flow use case and requirements of users before designing ideas are communicated using storyboards, wireframes, prototypes and/or mockups • Creating user-centered designs by understanding business requirements, and user feedback • Creates Storyboards wireframes, prototypes and/or mockups for leadership consideration and applicability to program strategic objectives • Develops process flows and or sitemaps • Capable of interacting with select data sets via multifaceted, multi-dimensional modalities such as two-dimensional (2D), three-dimensional (3D), and hybrid immersive virtual reality (VR), augmented reality (AR), or extended reality (XR) • Utilizes multi-modality tools, techniques, and applications designed to facilitate user access and dynamic visualization of geospatial data • Translates requirements into style guides, design systems, design patterns and attractive user interfaces • Ensures and applies coherent object perceptions that increase or add degrees of freedom (DoF), wider fields of view (FoV), and user controllable spatial awareness when viewing singular or integrated data feeds • Designs UI elements such as input controls, navigational components and informational components • Leverages geospatial artificial intelligence (GeoAI) tools and techniques to discover, access, analyze, display, render, and interact with specific geospatial data • Responsible for applying interactive and visual design principles on websites, web applications, and visualization tool • Identifying and troubleshooting UX problems • Incorporating customer feedback, usage metrics, and usability findings into design in order to enhance user experience • Working knowledge of the following technologies and software, Visio, HTML, CSS, Design Systems, and Adobe Creative Suite • Possess excellent writing and communications ability
B10: Project Manager | C10: • Plan, execute, and close projects that meet or exceed customer objectives • Create clear and attainable project objectives, build project requirements, and manage constraints of cost, time, scope, and quality • Develop the overall project plan and manage project operations • Manage the project stakeholders, project team, project risk, project schedule, project budget, and project conflicts • Ensure team members know and execute their respective roles and the roles of the other team members • Ensure production schedules are met and system resources are used effectively • Coordinate resolution of production-related problems • Ensures proper relationships are established between customers, teaming partners, and vendors to facilitate the delivery of information technology services • Prepares programmatic documentation and delivers associated customer/stakeholder briefings and reports
B11: Help Desk/Support Specialist | C11: • Responsible for providing technical assistance and support related to computer systems, hardware, or software • Responds to queries, runs diagnostic programs, isolates problem, and determines and implements solution • Writes training manuals • Trains computer users • Responds to email or chat messages for customers seeking help • Asks questions to determine nature of problem • Walks customers through problem-solving process • Runs diagnostic programs to resolve problems • Follows up with customers to ensure issue has been resolved • Gains feedback from customers about system usage • Runs reports to determine malfunctions that continue to occur
B12: Information Assurance/Security Specialist | C12: • Determines enterprise information assurance and security standards • Develops and implements information assurance/security standards and procedures • Coordinates, develops, and evaluates security programs for an organization • Recommends information assurance/security solutions to support customers' requirements • Identifies, reports, and resolves security violations • Supports customers at the highest levels in the development and implementation of doctrine and policies • Applies know-how to government and commercial common user systems, as well as to dedicated special purpose systems requiring specialized security features and procedures • Performs analysis, design, and development of security features for system architectures • Analyzes and defines security requirements for computer systems which may include mainframes, workstations, and personal computers • Designs, develops, engineers, and implements solutions that meet security requirements • Provides integration and implementation of the computer system security solution • Analyzes general information assurance-related technical problems and provides basic engineering and technical support in solving these problems • Performs vulnerability/risk analyses of computer systems and applications during all phases of the system development life cycle • Ensures that all information systems are functional and secure
B13: Software Engineer | C13: • Develops, maintains, and enhances complex and diverse software systems (e.g., processing-intensive analytics, novel algorithm development, manipulation of extremely large data sets, real-time systems, and business management information systems) based upon documented requirements • Leads the requirements analysis, design, modification, development, and implementation of software programming applications • Provides specific input to the software components of system design to include hardware/software trade-offs, software reuse, use of COTS/GOTS in place of new development, and requirements analysis and synthesis from system level to individual software components • Expertise in a variety of software concepts, practices, and procedures with more advanced experience and skills in specialized software products • Designs, implements, and integrates software applications or performs software engineering tasks • Utilizes software engineering and design methodologies appropriate to the development, integration, and production environment • Ensures efficient delivery of software engineering capabilities using industry standards and repeatable processes • Mitigates risks, controls costs and schedule variance, and effectively manages large scale, integrated software projects • Reviews and tests software components for adherence to the design requirements and documents test results • Reviews and approves test cases, processes, and impact assessments • Develops, reviews, and approves software documentation • Provides technical insight and advice to customers and senior leadership
B14: Systems Administrator | C14: • Perform systems administration of desktop and server systems connected to local and wide area networks • Desktop system management responsibilities involving account monitoring, security, Operating System (OS) installation, and other local area system administration related functions • Provide support for implementation, troubleshooting and maintenance of IT systems • Manage IT system infrastructure and any processes related to these systems • Provide support to IT systems including day-to-day operations, monitoring and problem resolution for all of the client/server/storage/network devices, mobile devices, etc. • Provide Tier 1 and Tier 2 problem identification, diagnosis and resolution of problem • Provide support for the escalation and communication of status to agency management and internal customers • Provide support for the dispatch system and hardware problems and remains involved in the resolution process • Configure and manage UNIX and Windows operating systems • Installs/loads operating system and application software • Isolate and resolve of hardware and software problems involving the applications, the operating system, the hardware, the communications infrastructure, or any combination thereof • Troubleshoot, maintain integrity and configure network components along with implementing operating systems enhancements to improve reliability and performance • Integrate new technologies into new and existing systems including the transition and migration of corporate system
B15: Systems Architect | C15: • Supports the development of cross functional or large-scale automated information systems to include enterprise architectures • Designs system architectures to include the software, hardware, and communications to support the total requirements and provides for present and future cross functional requirements and interfaces • Provides comprehensive definition of all aspects of system development from analysis of mission needs to verification of system performance • Performs evaluation of system alternatives and assessment of risks and costs
... B20: User Engagement / Training Specialist | C20: • Designs and executes a campaign plan aimed at obtaining wide spread adoption of existing and new capabilities. • Work with stakeholders and users to inform backlog prioritization. • Works with stakeholders and product management to align features and stories with solution level objectives. • Proactively engages Agile teams and release trains to ensure understanding of the mission user experience. • Delivers training programs, demonstrations, and workshops. • Monitors the effectiveness of training using individual or group performance results. • Collects feedback on sessions from attendees to use for future improvements to content and presentation. • Develops new training program design and existing program enhancements including lesson plans and other training materials.
B21: * = Key Personnel

Sheet Tab 4 IDIQ LCAT Rates
B2: DO NOT ALTER. DO NOT ADD ADDITIONAL LABOR CATEGORIES.
B4: Offeror's Name | C4: Escalation Rates: | K4: Escalation Rates: | S4: Escalation Rates: | AA4: Escalation Rates:
C5: Washington Fully Burdened Labor Rates (FBLRs) (Government Site) | K5: Washington FBLRs (Contractor Site) | S5: St Louis FBLRs (Government Site) | AA5: St Louis FBLRs (Contractor Site)
B6: IDIQ Labor Categories | C6: CY2023 | D6: CY2024 | E6: CY2025 | F6: CY2026 | G6: CY2027 | H6: CY2028 | I6: CY2029 | K6: CY2023 | L6: CY2024 | M6: CY2025 | N6: CY2026 | O6: CY2027 | P6: CY2028 | Q6: CY2029 | S6: CY2023 | T6: CY2024 | U6: CY2025 | V6: CY2026 | W6: CY2027 | X6: CY2028 | Y6: CY2029 | AA6: CY2023 | AB6: CY2024 | AC6: CY2025 | AD6: CY2026 | AE6: CY2027 | AF6: CY2028 | AG6: CY2029
B7: Program Manager | C7: 0 | D7: =C7*D$4 -> 0 | E7: =D7*E$4 -> 0 | F7: =E7*F$4 -> 0 | G7: =F7*G$4 -> 0 | H7: =G7*H$4 -> 0 | I7: =H7*I$4 -> 0 | K7: 0 | L7: =K7*L$4 -> 0 | M7: =L7*M$4 -> 0 | N7: =M7*N$4 -> 0 | O7: =N7*O$4 -> 0 | P7: =O7*P$4 -> 0 | Q7: =P7*Q$4 -> 0 | S7: 0 | T7: =S7*T$4 -> 0 | U7: =T7*U$4 -> 0 | V7: =U7*V$4 -> 0 | W7: =V7*W$4 -> 0 | X7: =W7*X$4 -> 0 | Y7: =X7*Y$4 -> 0 | AA7: 0 | AB7: =AA7*AB$4 -> 0 | AC7: =AB7*AC$4 -> 0 | AD7: =AC7*AD$4 -> 0 | AE7: =AD7*AE$4 -> 0 | AF7: =AE7*AF$4 -> 0 | AG7: =AF7*AG$4 -> 0
B8: Chief Software Architect (CSA) | C8: 0 | D8: =C8*D$4 -> 0 | E8: =D8*E$4 -> 0 | F8: =E8*F$4 -> 0 | G8: =F8*G$4 -> 0 | H8: =G8*H$4 -> 0 | I8: =H8*I$4 -> 0 | K8: 0 | L8: =K8*L$4 -> 0 | M8: =L8*M$4 -> 0 | N8: =M8*N$4 -> 0 | O8: =N8*O$4 -> 0 | P8: =O8*P$4 -> 0 | Q8: =P8*Q$4 -> 0 | S8: 0 | T8: =S8*T$4 -> 0 | U8: =T8*U$4 -> 0 | V8: =U8*V$4 -> 0 | W8: =V8*W$4 -> 0 | X8: =W8*X$4 -> 0 | Y8: =X8*Y$4 -> 0 | AA8: 0 | AB8: =AA8*AB$4 -> 0 | AC8: =AB8*AC$4 -> 0 | AD8: =AC8*AD$4 -> 0 | AE8: =AD8*AE$4 -> 0 | AF8: =AE8*AF$4 -> 0 | AG8: =AF8*AG$4 -> 0
B9: Chief Systems Engineer (CSE) | C9: 0 | D9: =C9*D$4 -> 0 | E9: =D9*E$4 -> 0 | F9: =E9*F$4 -> 0 | G9: =F9*G$4 -> 0 | H9: =G9*H$4 -> 0 | I9: =H9*I$4 -> 0 | K9: 0 | L9: =K9*L$4 -> 0 | M9: =L9*M$4 -> 0 | N9: =M9*N$4 -> 0 | O9: =N9*O$4 -> 0 | P9: =O9*P$4 -> 0 | Q9: =P9*Q$4 -> 0 | S9: 0 | T9: =S9*T$4 -> 0 | U9: =T9*U$4 -> 0 | V9: =U9*V$4 -> 0 | W9: =V9*W$4 -> 0 | X9: =W9*X$4 -> 0 | Y9: =X9*Y$4 -> 0 | AA9: 0 | AB9: =AA9*AB$4 -> 0 | AC9: =AB9*AC$4 -> 0 | AD9: =AC9*AD$4 -> 0 | AE9: =AD9*AE$4 -> 0 | AF9: =AE9*AF$4 -> 0 | AG9: =AF9*AG$4 -> 0
B10: Information Systems Security Officer (ISSO) | C10: 0 | D10: =C10*D$4 -> 0 | E10: =D10*E$4 -> 0 | F10: =E10*F$4 -> 0 | G10: =F10*G$4 -> 0 | H10: =G10*H$4 -> 0 | I10: =H10*I$4 -> 0 | K10: 0 | L10: =K10*L$4 -> 0 | M10: =L10*M$4 -> 0 | N10: =M10*N$4 -> 0 | O10: =N10*O$4 -> 0 | P10: =O10*P$4 -> 0 | Q10: =P10*Q$4 -> 0 | S10: 0 | T10: =S10*T$4 -> 0 | U10: =T10*U$4 -> 0 | V10: =U10*V$4 -> 0 | W10: =V10*W$4 -> 0 | X10: =W10*X$4 -> 0 | Y10: =X10*Y$4 -> 0 | AA10: 0 | AB10: =AA10*AB$4 -> 0 | AC10: =AB10*AC$4 -> 0 | AD10: =AC10*AD$4 -> 0 | AE10: =AD10*AE$4 -> 0 | AF10: =AE10*AF$4 -> 0 | AG10: =AF10*AG$4 -> 0
B11: UI / UX Engineer Jr. (Key) | C11: 0 | D11: =C11*D$4 -> 0 | E11: =D11*E$4 -> 0 | F11: =E11*F$4 -> 0 | G11: =F11*G$4 -> 0 | H11: =G11*H$4 -> 0 | I11: =H11*I$4 -> 0 | K11: 0 | L11: =K11*L$4 -> 0 | M11: =L11*M$4 -> 0 | N11: =M11*N$4 -> 0 | O11: =N11*O$4 -> 0 | P11: =O11*P$4 -> 0 | Q11: =P11*Q$4 -> 0 | S11: 0 | T11: =S11*T$4 -> 0 | U11: =T11*U$4 -> 0 | V11: =U11*V$4 -> 0 | W11: =V11*W$4 -> 0 | X11: =W11*X$4 -> 0 | Y11: =X11*Y$4 -> 0 | AA11: 0 | AB11: =AA11*AB$4 -> 0 | AC11: =AB11*AC$4 -> 0 | AD11: =AC11*AD$4 -> 0 | AE11: =AD11*AE$4 -> 0 | AF11: =AE11*AF$4 -> 0 | AG11: =AF11*AG$4 -> 0
B12: UI / UX Engineer Mid. (Key) | C12: 0 | D12: =C12*D$4 -> 0 | E12: =D12*E$4 -> 0 | F12: =E12*F$4 -> 0 | G12: =F12*G$4 -> 0 | H12: =G12*H$4 -> 0 | I12: =H12*I$4 -> 0 | K12: 0 | L12: =K12*L$4 -> 0 | M12: =L12*M$4 -> 0 | N12: =M12*N$4 -> 0 | O12: =N12*O$4 -> 0 | P12: =O12*P$4 -> 0 | Q12: =P12*Q$4 -> 0 | S12: 0 | T12: =S12*T$4 -> 0 | U12: =T12*U$4 -> 0 | V12: =U12*V$4 -> 0 | W12: =V12*W$4 -> 0 | X12: =W12*X$4 -> 0 | Y12: =X12*Y$4 -> 0 | AA12: 0 | AB12: =AA12*AB$4 -> 0 | AC12: =AB12*AC$4 -> 0 | AD12: =AC12*AD$4 -> 0 | AE12: =AD12*AE$4 -> 0 | AF12: =AE12*AF$4 -> 0 | AG12: =AF12*AG$4 -> 0
B13: UI / UX Engineer Sr. (Key) | C13: 0 | D13: =C13*D$4 -> 0 | E13: =D13*E$4 -> 0 | F13: =E13*F$4 -> 0 | G13: =F13*G$4 -> 0 | H13: =G13*H$4 -> 0 | I13: =H13*I$4 -> 0 | K13: 0 | L13: =K13*L$4 -> 0 | M13: =L13*M$4 -> 0 | N13: =M13*N$4 -> 0 | O13: =N13*O$4 -> 0 | P13: =O13*P$4 -> 0 | Q13: =P13*Q$4 -> 0 | S13: 0 | T13: =S13*T$4 -> 0 | U13: =T13*U$4 -> 0 | V13: =U13*V$4 -> 0 | W13: =V13*W$4 -> 0 | X13: =W13*X$4 -> 0 | Y13: =X13*Y$4 -> 0 | AA13: 0 | AB13: =AA13*AB$4 -> 0 | AC13: =AB13*AC$4 -> 0 | AD13: =AC13*AD$4 -> 0 | AE13: =AD13*AE$4 -> 0 | AF13: =AE13*AF$4 -> 0 | AG13: =AF13*AG$4 -> 0
B14: UI / UX Engineer SME (Key) | C14: 0 | D14: =C14*D$4 -> 0 | E14: =D14*E$4 -> 0 | F14: =E14*F$4 -> 0 | G14: =F14*G$4 -> 0 | H14: =G14*H$4 -> 0 | I14: =H14*I$4 -> 0 | K14: 0 | L14: =K14*L$4 -> 0 | M14: =L14*M$4 -> 0 | N14: =M14*N$4 -> 0 | O14: =N14*O$4 -> 0 | P14: =O14*P$4 -> 0 | Q14: =P14*Q$4 -> 0 | S14: 0 | T14: =S14*T$4 -> 0 | U14: =T14*U$4 -> 0 | V14: =U14*V$4 -> 0 | W14: =V14*W$4 -> 0 | X14: =W14*X$4 -> 0 | Y14: =X14*Y$4 -> 0 | AA14: 0 | AB14: =AA14*AB$4 -> 0 | AC14: =AB14*AC$4 -> 0 | AD14: =AC14*AD$4 -> 0 | AE14: =AD14*AE$4 -> 0 | AF14: =AE14*AF$4 -> 0 | AG14: =AF14*AG$4 -> 0
B15: Proj Mgt, Jr | C15: 0 | D15: =C15*D$4 -> 0 | E15: =D15*E$4 -> 0 | F15: =E15*F$4 -> 0 | G15: =F15*G$4 -> 0 | H15: =G15*H$4 -> 0 | I15: =H15*I$4 -> 0 | K15: 0 | L15: =K15*L$4 -> 0 | M15: =L15*M$4 -> 0 | N15: =M15*N$4 -> 0 | O15: =N15*O$4 -> 0 | P15: =O15*P$4 -> 0 | Q15: =P15*Q$4 -> 0 | S15: 0 | T15: =S15*T$4 -> 0 | U15: =T15*U$4 -> 0 | V15: =U15*V$4 -> 0 | W15: =V15*W$4 -> 0 | X15: =W15*X$4 -> 0 | Y15: =X15*Y$4 -> 0 | AA15: 0 | AB15: =AA15*AB$4 -> 0 | AC15: =AB15*AC$4 -> 0 | AD15: =AC15*AD$4 -> 0 | AE15: =AD15*AE$4 -> 0 | AF15: =AE15*AF$4 -> 0 | AG15: =AF15*AG$4 -> 0
B16: Proj Mgt, Mid | C16: 0 | D16: =C16*D$4 -> 0 | E16: =D16*E$4 -> 0 | F16: =E16*F$4 -> 0 | G16: =F16*G$4 -> 0 | H16: =G16*H$4 -> 0 | I16: =H16*I$4 -> 0 | K16: 0 | L16: =K16*L$4 -> 0 | M16: =L16*M$4 -> 0 | N16: =M16*N$4 -> 0 | O16: =N16*O$4 -> 0 | P16: =O16*P$4 -> 0 | Q16: =P16*Q$4 -> 0 | S16: 0 | T16: =S16*T$4 -> 0 | U16: =T16*U$4 -> 0 | V16: =U16*V$4 -> 0 | W16: =V16*W$4 -> 0 | X16: =W16*X$4 -> 0 | Y16: =X16*Y$4 -> 0 | AA16: 0 | AB16: =AA16*AB$4 -> 0 | AC16: =AB16*AC$4 -> 0 | AD16: =AC16*AD$4 -> 0 | AE16: =AD16*AE$4 -> 0 | AF16: =AE16*AF$4 -> 0 | AG16: =AF16*AG$4 -> 0
B17: Proj Mgt, Sr | C17: 0 | D17: =C17*D$4 -> 0 | E17: =D17*E$4 -> 0 | F17: =E17*F$4 -> 0 | G17: =F17*G$4 -> 0 | H17: =G17*H$4 -> 0 | I17: =H17*I$4 -> 0 | K17: 0 | L17: =K17*L$4 -> 0 | M17: =L17*M$4 -> 0 | N17: =M17*N$4 -> 0 | O17: =N17*O$4 -> 0 | P17: =O17*P$4 -> 0 | Q17: =P17*Q$4 -> 0 | S17: 0 | T17: =S17*T$4 -> 0 | U17: =T17*U$4 -> 0 | V17: =U17*V$4 -> 0 | W17: =V17*W$4 -> 0 | X17: =W17*X$4 -> 0 | Y17: =X17*Y$4 -> 0 | AA17: 0 | AB17: =AA17*AB$4 -> 0 | AC17: =AB17*AC$4 -> 0 | AD17: =AC17*AD$4 -> 0 | AE17: =AD17*AE$4 -> 0 | AF17: =AE17*AF$4 -> 0 | AG17: =AF17*AG$4 -> 0
B18: Proj Mgt, SME | C18: 0 | D18: =C18*D$4 -> 0 | E18: =D18*E$4 -> 0 | F18: =E18*F$4 -> 0 | G18: =F18*G$4 -> 0 | H18: =G18*H$4 -> 0 | I18: =H18*I$4 -> 0 | K18: 0 | L18: =K18*L$4 -> 0 | M18: =L18*M$4 -> 0 | N18: =M18*N$4 -> 0 | O18: =N18*O$4 -> 0 | P18: =O18*P$4 -> 0 | Q18: =P18*Q$4 -> 0 | S18: 0 | T18: =S18*T$4 -> 0 | U18: =T18*U$4 -> 0 | V18: =U18*V$4 -> 0 | W18: =V18*W$4 -> 0 | X18: =W18*X$4 -> 0 | Y18: =X18*Y$4 -> 0 | AA18: 0 | AB18: =AA18*AB$4 -> 0 | AC18: =AB18*AC$4 -> 0 | AD18: =AC18*AD$4 -> 0 | AE18: =AD18*AE$4 -> 0 | AF18: =AE18*AF$4 -> 0 | AG18: =AF18*AG$4 -> 0
... B58: User Engagement / Training Specialist, SME (Key) | C58: 0 | D58: =C58*D$4 -> 0 | E58: =D58*E$4 -> 0 | F58: =E58*F$4 -> 0 | G58: =F58*G$4 -> 0 | H58: =G58*H$4 -> 0 | I58: =H58*I$4 -> 0 | K58: 0 | L58: =K58*L$4 -> 0 | M58: =L58*M$4 -> 0 | N58: =M58*N$4 -> 0 | O58: =N58*O$4 -> 0 | P58: =O58*P$4 -> 0 | Q58: =P58*Q$4 -> 0 | S58: 0 | T58: =S58*T$4 -> 0 | U58: =T58*U$4 -> 0 | V58: =U58*V$4 -> 0 | W58: =V58*W$4 -> 0 | X58: =W58*X$4 -> 0 | Y58: =X58*Y$4 -> 0 | AA58: 0 | AB58: =AA58*AB$4 -> 0 | AC58: =AB58*AC$4 -> 0 | AD58: =AC58*AD$4 -> 0 | AE58: =AD58*AE$4 -> 0 | AF58: =AE58*AF$4 -> 0 | AG58: =AF58*AG$4 -> 0

Sheet Tab 5 IDIQ and TO1 CLINs
D2: Stratus CLIN Structure | J2: Strata TO 001 CLIN Structure
B3: CLIN | C3: Sub-CLIN | D3: IDIQ - Functional & Capability Areas | E3: Contract Type | F3: Funding Type | H3: CLIN | I3: Sub-CLIN | J3: TO 001- Functional & Capability Areas | K3: Contract Type | L3: Funding Type
B4: X001 | D4: Operations and Sustainment | E4: Firm Fixed Price (FFP) | F4: Operations and Maintenance (O&M) | H4: X001 | J4: Operations and Sustainment | K4: Firm Fixed Price (FFP) | L4: Operations and Maintenance (O&M)
B5: X001 | C5: AA | D5: Operations & Sustainment: MapStack | E5: Not Sepeately Priced (NSP) | F5: NSP | H5: X001 | I5: AA | J5: Operations & Sustainment: MapStack | K5: Not Sepeately Priced (NSP) | L5: NSP
B6: X001 | C6: AB | D6: Operations & Sustainment: ICGIS Portal | E6: NSP | F6: NSP | H6: X001 | I6: AB | J6: Operations & Sustainment: ICGIS Portal | K6: NSP | L6: NSP
B7: X001 | C7: AC | D7: Operations & Sustainment: Google Earth | E7: NSP | F7: NSP | H7: X001 | I7: AC | J7: Operations & Sustainment: Google Earth | K7: NSP | L7: NSP
B8: X001 | C8: AD | D8: Operations & Sustainment: SOM Discovery | E8: NSP | F8: NSP | H8: X001 | I8: AD | J8: Operations & Sustainment: SOM Discovery | K8: NSP | L8: NSP
B9: X001 | C9: AE | D9: Operations & Sustainment: USFK | E9: NSP | F9: NSP | H9: X001 | I9: AE | J9: Operations & Sustainment: USFK | K9: NSP | L9: NSP
B10: X001 | C10: AF | D10: Operations & Sustainment: Transition | E10: FFP | F10: O&M | H10: X001 | I10: AF | J10: Operations & Sustainment: Transition | K10: FFP | L10: O&M
B11: X002 | D11: Modernization, New Capability Development, Prototypes, Engineering Assessments | E11: Labor Hour (LH) | F11: Research, Development, Test and Engineering (RDT&E) | H11: X002 | J11: Modernization, New Capability Development, Prototypes, Engineering Assessments | K11: Labor Hour (LH) | L11: Research, Development, Test and Engineering (RDT&E)
B12: X003 | D12: Sensors: Operations and Sustainment | H12: X003 | J12: Sensors: Operations and Sustainment
B13: X003 | C13: AA | D13: Operations & Sustainment: LSeg | E13: FFP | F13: O&M | H13: X003 | I13: AA | J13: Operations & Sustainment: LSeg | K13: FFP | L13: O&M
B14: X003 | C14: AB | D14: Operations & Sustainment: NSeg | E14: FFP | F14: O&M | H14: X003 | I14: AB | J14: Operations & Sustainment: NSeg | K14: FFP | L14: O&M
B15: X003 | C15: AC | D15: Operations & Sustainment: Enterprise Testing | E15: LH | F15: O&M | H15: X003 | I15: AC | J15: Operations & Sustainment: Enterprise Testing | K15: LH | L15: O&M
B16: X003 | C16: AD | D16: Operations & Sustainment: Other | E16: FFP | F16: O&M | H16: X004 | J16: LSeg Sensor | K16: LH | L16: RDT&E
B17: X004 | D17: LSeg Sensor | E17: LH | F17: RDT&E | H17: X005 | J17: NSeg Sensor | K17: LH | L17: RDT&E
B18: X005 | D18: NSeg Sensor | E18: LH | F18: RDT&E | H18: X010 | J18: ODC
B19: X006 | D19: New Sensor | E19: LH | F19: RDT&E | H19: X010 | I19: AA | J19: Material SW | K19: CR | L19: O&M
B20: X007 | D20: Surge: Operations and Sustainment | E20: FFP | F20: O&M | H20: X010 | I20: AB | J20: Material HW | K20: CR | L20: O&M
B21: X008 | D21: Surge: Software Development (FFP) | E21: FFP | F21: RDT&E | H21: X010 | I21: AC | J21: Travel | K21: CR | L21: O&M
B22: X009 | D22: Surge: Software Development (LH) | E22: LH | F22: RDT&E | H22: X010 | I22: AD | J22: Misc/Other | K22: CR | L22: O&M
B23: X010 | D23: ODC
B24: X010 | C24: AA | D24: Material SW | E24: Cost Reimburseable (CR) | F24: O&M
B25: X010 | C25: AB | D25: Material HW | E25: CR | F25: O&M
B26: X010 | C26: AC | D26: Travel | E26: CR | F26: O&M
B27: X010 | C27: AD | D27: Misc/Other | E27: CR | F27: O&M

Sheet Tab 6 TO1 CLIN X001
B3: Instructions: CLIN X001 has a Base Period (BP) and Four Option Years (OYs). Offerors shall propose appropriate LCATs/Skill mix as determined by the Offeror to satisfy the Strata requirements. List all Labor Categories associated with CLIN X001 and all X001 sub-CLINs (except X001AF) that are not seperately priced. Insert rows as needed. Ensure equations in the blue cells are copied down to inserted rows and summation equations are maintained. All FBLRs must tie back to the IDIQ LCAT FBLRs.
B5: CLIN | C5: Labor Category | D5: Skill Level (Jr, Mid, Sr, SME) | E5: Work Location (Washington or STL) | F5: Primary Work Site (Gov or Ktr) | G5: Hours | H5: Fully Burdened Hourly Rate | I5: Price | K5: Color Key
B6: BP - CLIN 0001 | I6: =G6*H6 -> 0 | K6: Do Not Edit
I7: =G7*H7 -> 0 | K7: Do Not Edit
I8: =G8*H8 -> 0 | K8: Enter Data Here
I9: =G9*H9 -> 0
I10: =G10*H10 -> 0
F11: BP Total Hours | G11: =SUM(G6:G10) -> 0 | H11: BP Total Price | I11: =SUM(I6:I10) -> 0
B13: OY1 - CLIN 1001 | I13: =G13*H13 -> 0
I14: =G14*H14 -> 0
I15: =G15*H15 -> 0
I16: =G16*H16 -> 0
I17: =G17*H17 -> 0
F18: OY1 Total Hours | G18: =SUM(G13:G17) -> 0 | H18: OY1 Total Price | I18: =SUM(I13:I17) -> 0
B20: OY2 - CLIN 2001 | I20: =G20*H20 -> 0
I21: =G21*H21 -> 0
I22: =G22*H22 -> 0
I23: =G23*H23 -> 0
I24: =G24*H24 -> 0
F25: OY2 Total Hours | G25: =SUM(G20:G24) -> 0 | H25: OY2 Total Price | I25: =SUM(I20:I24) -> 0
B27: OY3 - CLIN 3001 | I27: =G27*H27 -> 0
I28: =G28*H28 -> 0
I29: =G29*H29 -> 0
I30: =G30*H30 -> 0
I31: =G31*H31 -> 0
F32: OY3 Total Hours | G32: =SUM(G27:G31) -> 0 | H32: OY3 Total Price | I32: =SUM(I27:I31) -> 0
B34: OY4 - CLIN 4001 | I34: =G34*H34 -> 0
I35: =G35*H35 -> 0
I36: =G36*H36 -> 0
I37: =G37*H37 -> 0
I38: =G38*H38 -> 0
F39: OY4 Total Hours | G39: =SUM(G34:G38) -> 0 | H39: OY4 Total Price | I39: =SUM(I34:I38) -> 0
H42: CLIN X001 Total Price (Base and Option Years) | I42: =I11+I18+I25+I32+I39 -> 0

Sheet Tab 7 TO1 SUBCLIN X001AF
B3: Instructions: SUBCLIN X001AF is a BP Only. Offerors shall propose appropriate LCATs/Skill mix as determined by the Offeror to satisfy the Strata requirements. Insert rows as needed. Ensure equations in the blue cells are copied down to inserted rows and summation equations are maintained. All FBLRs must tie back to the IDIQ LCAT FBLRs.
B5: SUBCLIN | C5: Labor Category | D5: Skill Level (Jr, Mid, Sr, SME) | E5: Work Location (Washington or STL) | F5: Primary Work Site (Gov or Ktr) | G5: Hours | H5: FBLR | I5: Price | K5: Color Key
B6: BP - SUBCLIN 0001AF | I6: =G6*H6 -> 0 | K6: Do Not Edit
I7: =G7*H7 -> 0 | K7: Do Not Edit
I8: =G8*H8 -> 0 | K8: Enter Data Here
I9: =G9*H9 -> 0
I10: =G10*H10 -> 0
F11: BP Total Hours | G11: =SUM(G6:G10) -> 0 | H11: BP Total Price | I11: =SUM(I6:I10) -> 0

Sheet Tab 8 TO1 CLIN X002
B3: Instructions: CLIN X002 has a Base Period and Four Option Years. Offerors shall utilize the total hours provided for each PoP. Offerors shall propose appropriate LCATs/Skill mix as determined by the Offeror to satisfy the Strata requirements. Proposed hours must equal the Government provided total hours for each PoP. Insert rows as needed. Ensure equations in the blue cells are copied down to inserted rows and summation equations are maintained. All FBLRs must tie back to the IDIQ LCAT FBLRs.
B5: CLIN | C5: Labor Category | D5: Skill Level (Jr, Mid, Sr, SME) | E5: Work Location (Washington or STL) | F5: Primary Work Site (Gov or Ktr) | G5: Hours | H5: FBLR | I5: Price | K5: Color Key
B6: BP - CLIN 0002 | I6: =G6*H6 -> 0 | K6: Do Not Edit
I7: =G7*H7 -> 0 | K7: Do Not Edit
I8: =G8*H8 -> 0 | K8: Enter Data Here
I9: =G9*H9 -> 0
I10: =G10*H10 -> 0
F11: BP Proposed Total Hours | G11: =SUM(G6:G10) -> 0 | H11: BP Total Price | I11: =SUM(I6:I10) -> 0
F12: DO NOT ALTER - Government Provided BP Total Hours | G12: 18290
B14: OY1 - CLIN 1002 | I14: =G14*H14 -> 0
I15: =G15*H15 -> 0
I16: =G16*H16 -> 0
I17: =G17*H17 -> 0
I18: =G18*H18 -> 0
F19: Offeror Proposed OY1 Total Hours | G19: =SUM(G14:G18) -> 0 | H19: OY1 Total Price | I19: =SUM(I14:I18) -> 0
F20: DO NOT ALTER - Government Provided OY1 Total Hours | G20: 21948
B22: OY2 - CLIN 2002 | I22: =G22*H22 -> 0
I23: =G23*H23 -> 0
I24: =G24*H24 -> 0
I25: =G25*H25 -> 0
I26: =G26*H26 -> 0
F27: Offeror Proposed OY2 Total Hours | G27: =SUM(G22:G26) -> 0 | H27: OY2 Total Price | I27: =SUM(I22:I26) -> 0
F28: DO NOT ALTER - Government Provided OY2 Total Hours | G28: 21948
B30: OY3 - CLIN 3002 | I30: =G30*H30 -> 0
I31: =G31*H31 -> 0
I32: =G32*H32 -> 0
I33: =G33*H33 -> 0
I34: =G34*H34 -> 0
F35: Offeror Proposed OY3 Total Hours | G35: =SUM(G30:G34) -> 0 | H35: OY3 Total Price | I35: =SUM(I30:I34) -> 0
F36: DO NOT ALTER - Government Provided OY3 Total Hours | G36: 21948
B38: OY4 - CLIN 4002 | I38: =G38*H38 -> 0
I39: =G39*H39 -> 0
I40: =G40*H40 -> 0
I41: =G41*H41 -> 0
I42: =G42*H42 -> 0
F43: Offeror Proposed OY4 Total Hours | G43: =SUM(G38:G42) -> 0 | H43: OY4 Total Price | I43: =SUM(I38:I42) -> 0
F44: DO NOT ALTER - Government Provided OY4 Total Hours | G44: 21948
H47: CLIN X002 Total Price (Base and Option Years) | I47: =I11+I19+I27+I35+I43 -> 0

Sheet Tab 9 O1 SUBCLIN X003AA
B3: Instructions: SUBCLIN X003AA has a BP and Four OYs. Offerors shall propose appropriate LCATs/Skill mix as determined by the Offeror to satisfy the Strata requirements. Insert rows as needed. Ensure equations in the blue cells are copied down to inserted rows and summation equations are maintained. All FBLRs must tie back to the IDIQ LCAT FBLRs.
B5: SUBCLIN | C5: Labor Category | D5: Skill Level (Jr, Mid, Sr, SME) | E5: Work Location (Washington or STL) | F5: Primary Work Site (Gov or Ktr) | G5: Hours | H5: FBLR | I5: Price | K5: Color Key
B6: BP - SUBCLIN 0003AA | I6: =G6*H6 -> 0 | K6: Do Not Edit
I7: =G7*H7 -> 0 | K7: Do Not Edit
I8: =G8*H8 -> 0 | K8: Enter Data Here
I9: =G9*H9 -> 0
I10: =G10*H10 -> 0
F11: BP Total Hours | G11: =SUM(G6:G10) -> 0 | H11: BP Total Price | I11: =SUM(I6:I10) -> 0
B13: OY1 - SUBCLIN 1003AA | I13: =G13*H13 -> 0
I14: =G14*H14 -> 0
I15: =G15*H15 -> 0
I16: =G16*H16 -> 0
I17: =G17*H17 -> 0
F18: OY1 Total Hours | G18: =SUM(G13:G17) -> 0 | H18: OY1 Total Price | I18: =SUM(I13:I17) -> 0
B20: OY2 - SUBCLIN 2003AA | I20: =G20*H20 -> 0
I21: =G21*H21 -> 0
I22: =G22*H22 -> 0
I23: =G23*H23 -> 0
I24: =G24*H24 -> 0
F25: OY2 Total Hours | G25: =SUM(G20:G24) -> 0 | H25: OY2 Total Price | I25: =SUM(I20:I24) -> 0
B27: OY3 - SUBCLIN 3003AA | I27: =G27*H27 -> 0
I28: =G28*H28 -> 0
I29: =G29*H29 -> 0
I30: =G30*H30 -> 0
I31: =G31*H31 -> 0
F32: OY3 Total Hours | G32: =SUM(G27:G31) -> 0 | H32: OY3 Total Price | I32: =SUM(I27:I31) -> 0
B34: OY4 - SUBCLIN 4003AA | I34: =G34*H34 -> 0
I35: =G35*H35 -> 0
I36: =G36*H36 -> 0
I37: =G37*H37 -> 0
I38: =G38*H38 -> 0
F39: OY4 Total Hours | G39: =SUM(G34:G38) -> 0 | H39: OY4 Total Price | I39: =SUM(I34:I38) -> 0
H42: SUBCLIN X003AA Total Price (Base and Option Years) | I42: =I11+I18+I25+I32+I39 -> 0

Sheet Tab 10 TO1 SUBCLIN X003AB
B3: Instructions: SUBCLIN X003AB has a BP and Four OYs. Offerors shall propose appropriate LCATs/Skill mix as determined by the Offeror to satisfy the Strata requirements. Insert rows as needed. Ensure equations in the blue cells are copied down to inserted rows and summation equations are maintained. All FBLRs must tie back to the IDIQ LCAT FBLRs.
B5: SUBCLIN | C5: Labor Category | D5: Skill Level (Jr, Mid, Sr, SME) | E5: Work Location (Washington or STL) | F5: Primary Work Site (Gov or Ktr) | G5: Hours | H5: FBLR | I5: Price | K5: Color Key
B6: BP - SUBCLIN 0003AB | I6: =G6*H6 -> 0 | K6: Do Not Edit
I7: =G7*H7 -> 0 | K7: Do Not Edit
I8: =G8*H8 -> 0 | K8: Enter Data Here
I9: =G9*H9 -> 0
I10: =G10*H10 -> 0
F11: BP Total Hours | G11: =SUM(G6:G10) -> 0 | H11: BP Total Price | I11: =SUM(I6:I10) -> 0
B13: OY1 - SUBCLIN 1003AB | I13: =G13*H13 -> 0
I14: =G14*H14 -> 0
I15: =G15*H15 -> 0
I16: =G16*H16 -> 0
I17: =G17*H17 -> 0
F18: OY1 Total Hours | G18: =SUM(G13:G17) -> 0 | H18: OY1 Total Price | I18: =SUM(I13:I17) -> 0
B20: OY2 - SUBCLIN 2003AB | I20: =G20*H20 -> 0
I21: =G21*H21 -> 0
I22: =G22*H22 -> 0
I23: =G23*H23 -> 0
I24: =G24*H24 -> 0
F25: OY2 Total Hours | G25: =SUM(G20:G24) -> 0 | H25: OY2 Total Price | I25: =SUM(I20:I24) -> 0
B27: OY3 - SUBCLIN 3003AB | I27: =G27*H27 -> 0
I28: =G28*H28 -> 0
I29: =G29*H29 -> 0
I30: =G30*H30 -> 0
I31: =G31*H31 -> 0
F32: OY3 Total Hours | G32: =SUM(G27:G31) -> 0 | H32: OY3 Total Price | I32: =SUM(I27:I31) -> 0
B34: OY4 - SUBCLIN 4003AB | I34: =G34*H34 -> 0
I35: =G35*H35 -> 0
I36: =G36*H36 -> 0
I37: =G37*H37 -> 0
I38: =G38*H38 -> 0
F39: OY4 Total Hours | G39: =SUM(G34:G38) -> 0 | H39: OY4 Total Price | I39: =SUM(I34:I38) -> 0
H42: SUBCLIN X003AB Total Price (Base and Option Years) | I42: =I11+I18+I25+I32+I39 -> 0

Sheet Tab 11 TO1 SUBCLIN X003AC
B3: Instructions: SUBCLIN X003AC has a BP and Four OYs. Offerors shall utilize the total hours provided for each PoP. Offerors shall propose appropriate LCATs/Skill mix as determined by the Offeror to satisfy the Strata requirements. Proposed hours must equal the Government provided total hours for each PoP. Insert rows as needed. Ensure equations in the blue cells are copied down to inserted rows and summation equations are maintained. All FBLRs must tie back to the IDIQ LCAT FBLRs.
B5: SUBCLIN | C5: Labor Category | D5: Skill Level (Jr, Mid, Sr, SME) | E5: Work Location (Washington or STL) | F5: Primary Work Site (Gov or Ktr) | G5: Hours | H5: FBLR | I5: Price | K5: Color Key
B6: BP - SUBCLIN 0003AC | I6: =G6*H6 -> 0 | K6: Do Not Edit
I7: =G7*H7 -> 0 | K7: Do Not Edit
I8: =G8*H8 -> 0 | K8: Enter Data Here
I9: =G9*H9 -> 0
I10: =G10*H10 -> 0
F11: BP Proposed Total Hours | G11: =SUM(G6:G10) -> 0 | H11: BP Total Price | I11: =SUM(I6:I10) -> 0
F12: DO NOT ALTER - Government Provided BP Total Hours | G12: 2325
B13: OY1 - SUBCLIN 1003AC
I14: =G14*H14 -> 0
I15: =G15*H15 -> 0
I16: =G16*H16 -> 0
I17: =G17*H17 -> 0
I18: =G18*H18 -> 0
F19: Offeror Proposed OY1 Total Hours | G19: =SUM(G14:G18) -> 0 | H19: OY1 Total Price | I19: =SUM(I14:I18) -> 0
B20: OY2 - SUBCLIN 2003AC | F20: DO NOT ALTER - Government Provided OY1 Total Hours | G20: 2790
I22: =G22*H22 -> 0
I23: =G23*H23 -> 0
I24: =G24*H24 -> 0
I25: =G25*H25 -> 0
I26: =G26*H26 -> 0
B27: OY3 - SUBCLIN 3003AC | F27: Offeror Proposed OY2 Total Hours | G27: =SUM(G22:G26) -> 0 | H27: OY2 Total Price | I27: =SUM(I22:I26) -> 0
F28: DO NOT ALTER - Government Provided OY2 Total Hours | G28: 2790
I30: =G30*H30 -> 0
I31: =G31*H31 -> 0
I32: =G32*H32 -> 0
I33: =G33*H33 -> 0
B34: OY4 - SUBCLIN 4003AC | I34: =G34*H34 -> 0
F35: Offeror Proposed OY3 Total Hours | G35: =SUM(G30:G34) -> 0 | H35: OY3 Total Price | I35: =SUM(I30:I34) -> 0
F36: DO NOT ALTER - Government Provided OY3 Total Hours | G36: 2790
I38: =G38*H38 -> 0
I39: =G39*H39 -> 0
I40: =G40*H40 -> 0
I41: =G41*H41 -> 0
I42: =G42*H42 -> 0
F43: Offeror Proposed OY4 Total Hours | G43: =SUM(G38:G42) -> 0 | H43: OY4 Total Price | I43: =SUM(I38:I42) -> 0
F44: DO NOT ALTER - Government Provided OY4 Total Hours | G44: 2790
H47: SUBCLIN X003AC Total Price (Base and Option Years) | I47: =I11+I19+I27+I35+I43 -> 0

Sheet Tab 12 TO1 CLIN X004
B3: Instructions: CLIN X004 has a BP and Four OYs. Offerors shall utilize the total hours provided for each PoP. Offerors shall propose appropriate LCATs/Skill mix as determined by the Offeror to satisfy the Strata requirements. Proposed hours must equal the Government provided total hours for each PoP. Insert rows as needed. Ensure equations in the blue cells are copied down to inserted rows and summation equations are maintained. All FBLRs must tie back to the IDIQ LCAT FBLRs.
B5: CLIN | C5: Labor Category | D5: Skill Level (Jr, Mid, Sr, SME) | E5: Work Location (Washington or STL) | F5: Primary Work Site (Gov or Ktr) | G5: Hours | H5: FBLR | I5: Price | K5: Color Key
B6: BP - CLIN 0004 | I6: =G6*H6 -> 0 | K6: Do Not Edit
I7: =G7*H7 -> 0 | K7: Do Not Edit
I8: =G8*H8 -> 0 | K8: Enter Data Here
I9: =G9*H9 -> 0
I10: =G10*H10 -> 0
F11: BP Proposed Total Hours | G11: =SUM(G6:G10) -> 0 | H11: BP Total Price | I11: =SUM(I6:I10) -> 0
F12: DO NOT ALTER - Government Provided BP Total Hours | G12: 12865
B14: OY1 - CLIN 1004 | I14: =G14*H14 -> 0
I15: =G15*H15 -> 0
I16: =G16*H16 -> 0
I17: =G17*H17 -> 0
I18: =G18*H18 -> 0
F19: Offeror Proposed OY1 Total Hours | G19: =SUM(G14:G18) -> 0 | H19: OY1 Total Price | I19: =SUM(I14:I18) -> 0
F20: DO NOT ALTER - Government Provided OY1 Total Hours | G20: 15438
B22: OY2 - CLIN 2004 | I22: =G22*H22 -> 0
I23: =G23*H23 -> 0
I24: =G24*H24 -> 0
I25: =G25*H25 -> 0
I26: =G26*H26 -> 0
F27: Offeror Proposed OY2 Total Hours | G27: =SUM(G22:G26) -> 0 | H27: OY2 Total Price | I27: =SUM(I22:I26) -> 0
F28: DO NOT ALTER - Government Provided OY2 Total Hours | G28: 15438
B30: OY3 - CLIN 3004 | I30: =G30*H30 -> 0
I31: =G31*H31 -> 0
I32: =G32*H32 -> 0
I33: =G33*H33 -> 0
I34: =G34*H34 -> 0
F35: Offeror Proposed OY3 Total Hours | G35: =SUM(G30:G34) -> 0 | H35: OY3 Total Price | I35: =SUM(I30:I34) -> 0
F36: DO NOT ALTER - Government Provided OY3 Total Hours | G36: 15438
B38: OY4 - CLIN 4004 | I38: =G38*H38 -> 0
I39: =G39*H39 -> 0
I40: =G40*H40 -> 0
I41: =G41*H41 -> 0
I42: =G42*H42 -> 0
F43: Offeror Proposed OY4 Total Hours | G43: =SUM(G38:G42) -> 0 | H43: OY4 Total Price | I43: =SUM(I38:I42) -> 0
F44: DO NOT ALTER - Government Provided OY4 Total Hours | G44: 15438
H47: CLIN X004 Total Price (Base and Option Years) | I47: =I11+I19+I27+I35+I43 -> 0

Sheet Tab 13 TO1 CLIN X005
B3: Instructions: CLIN X005 is a BP and OY Only. Offerors shall utilize the total hours provided for each PoP. Offerors shall propose appropriate LCATs/Skill mix as determined by the Offeror to satisfy the Strata requirements. Proposed hours must equal the Government provided total hours for each PoP. Insert rows as needed. Ensure equations in the blue cells are copied down to inserted rows and summation equations are maintained. All FBLRs must tie back to the IDIQ LCAT FBLRs.
B5: CLIN | C5: Labor Category | D5: Skill Level (Jr, Mid, Sr, SME) | E5: Work Location (Washington or STL) | F5: Primary Work Site (Gov or Ktr) | G5: Hours | H5: FBLR | I5: Price | K5: Color Key
B6: BP - CLIN 0005 | I6: =G6*H6 -> 0 | K6: Do Not Edit
I7: =G7*H7 -> 0 | K7: Do Not Edit
I8: =G8*H8 -> 0 | K8: Enter Data Here
I9: =G9*H9 -> 0
I10: =G10*H10 -> 0
F11: BP Proposed Total Hours | G11: =SUM(G6:G10) -> 0 | H11: BP Total Price | I11: =SUM(I6:I10) -> 0
F12: DO NOT ALTER - Government Provided BP Total Hours | G12: 1395
B14: OY1 - CLIN 1005 | I14: =G14*H14 -> 0
I15: =G15*H15 -> 0
I16: =G16*H16 -> 0
I17: =G17*H17 -> 0
I18: =G18*H18 -> 0
F19: Offeror Proposed OY1 Total Hours | G19: =SUM(G14:G18) -> 0 | H19: OY1 Total Price | I19: =SUM(I14:I18) -> 0
F20: DO NOT ALTER - Government Provided OY1 Total Hours | G20: 1488
H23: CLIN X005 Total Price (Base and Option Year) | I23: =I11+I19 -> 0

Sheet Tab 14 TO1 Summary
C2: Instructions
C3: Do not edit anything on this Tab.
B6: Total Price for Task Order 0001
B7: CLIN No. | C7: CLIN Title | D7: Cost/Price | E7: Period of Performance | F7: Notes | I7: Color Key
B8: 0001 | C8: Base Period - Operations and Sustainment | D8: ='Tab 6 TO1 CLIN X001'!I11 -> 0 | E8: 9 Months | F8: CLIN X001 | I8: Do Not Edit
B9: 1001 | C9: Option Year 1 - Operations and Sustainment | D9: ='Tab 6 TO1 CLIN X001'!I18 -> 0 | E9: 12 Months | I9: Do Not Edit
B10: 2001 | C10: Option Year 2 - Operations and Sustainment | D10: ='Tab 6 TO1 CLIN X001'!I25 -> 0 | E10: 12 Months | I10: Enter Data Here
B11: 3001 | C11: Option Year 3 - Operations and Sustainment | D11: ='Tab 6 TO1 CLIN X001'!I32 -> 0 | E11: 12 Months
B12: 4001 | C12: Option Year 4 - Operations and Sustainment | D12: ='Tab 6 TO1 CLIN X001'!I39 -> 0 | E12: 12 Months
B13: 0001AF | C13: Transition | D13: ='Tab 7 TO1 SUBCLIN X001AF'!I11 -> 0 | E13: 3 Months
B15: 0002 | C15: Base Period - Modernization, New Capability Development, Prototypes, Engineering Assessments | D15: ='Tab 8 TO1 CLIN X002'!I11 -> 0 | E15: 9 Months | F15: CLIN X002
B16: 1002 | C16: Option Year 1 - Modernization, New Capability Development, Prototypes, Engineering Assessments | D16: ='Tab 8 TO1 CLIN X002'!I19 -> 0 | E16: 12 Months
B17: 2002 | C17: Option Year 2 - Modernization, New Capability Development, Prototypes, Engineering Assessments | D17: ='Tab 8 TO1 CLIN X002'!I27 -> 0 | E17: 12 Months
B18: 3002 | C18: Option Year 3 - Modernization, New Capability Development, Prototypes, Engineering Assessments | D18: ='Tab 8 TO1 CLIN X002'!I35 -> 0 | E18: 12 Months
B19: 4002 | C19: Option Year 4 - Modernization, New Capability Development, Prototypes, Engineering Assessments | D19: ='Tab 8 TO1 CLIN X002'!I43 -> 0 | E19: 12 Months
B21: 0003AA | C21: Base Period - Operations & Sustainment: LSeg | D21: ='Tab 9 O1 SUBCLIN X003AA'!I11 -> 0 | E21: 9 Months | F21: CLIN X003AA
B22: 1003AA | C22: Option Year 1 - Operations & Sustainment: LSeg | D22: ='Tab 9 O1 SUBCLIN X003AA'!I18 -> 0 | E22: 12 Months
B23: 2003AA | C23: Option Year 2 - Operations & Sustainment: LSeg | D23: ='Tab 9 O1 SUBCLIN X003AA'!I25 -> 0 | E23: 12 Months
B24: 3003AA | C24: Option Year 3 - Operations & Sustainment: LSeg | D24: ='Tab 9 O1 SUBCLIN X003AA'!I32 -> 0 | E24: 12 Months
B25: 4003AA | C25: Option Year 4 - Operations & Sustainment: LSeg | D25: ='Tab 9 O1 SUBCLIN X003AA'!I39 -> 0 | E25: 12 Months
B27: 0003AB | C27: Base Period - Operations & Sustainment: NSeg | D27: ='Tab 10 TO1 SUBCLIN X003AB'!I11 -> 0 | E27: 9 Months | F27: CLIN X003AB
B28: 1003AB | C28: Option Year 1 - Operations & Sustainment: NSeg | D28: ='Tab 10 TO1 SUBCLIN X003AB'!I18 -> 0 | E28: 12 Months
B29: 2003AB | C29: Option Year 2 - Operations & Sustainment: NSeg | D29: ='Tab 10 TO1 SUBCLIN X003AB'!I25 -> 0 | E29: 12 Months
B30: 3003AB | C30: Option Year 3 - Operations & Sustainment: NSeg | D30: ='Tab 10 TO1 SUBCLIN X003AB'!I32 -> 0 | E30: 12 Months
B31: 4003AB | C31: Option Year 4 - Operations & Sustainment: NSeg | D31: ='Tab 10 TO1 SUBCLIN X003AB'!I39 -> 0 | E31: 12 Months
B33: 0003AC | C33: Base Period - Operations & Sustainment: Enterprise Testing | D33: ='Tab 11 TO1 SUBCLIN X003AC'!I11 -> 0 | E33: 9 Months | F33: CLIN X003AC
B34: 1003AC | C34: Option Year 1 - Operations & Sustainment: Enterprise Testing | D34: ='Tab 11 TO1 SUBCLIN X003AC'!I19 -> 0 | E34: 12 Months
B35: 2003AC | C35: Option Year 2 - Operations & Sustainment: Enterprise Testing | D35: ='Tab 11 TO1 SUBCLIN X003AC'!I27 -> 0 | E35: 12 Months
B36: 3003AC | C36: Option Year 3 - Operations & Sustainment: Enterprise Testing | D36: ='Tab 11 TO1 SUBCLIN X003AC'!I35 -> 0 | E36: 12 Months
B37: 4003AC | C37: Option Year 4 - Operations & Sustainment: Enterprise Testing | D37: ='Tab 11 TO1 SUBCLIN X003AC'!I43 -> 0 | E37: 12 Months
B39: 0004 | C39: Base Period - Lseg Sensor | D39: ='Tab 12 TO1 CLIN X004'!I11 -> 0 | E39: 9 Months | F39: CLIN X004
B40: 1004 | C40: Option Year 1 - Lseg Sensor | D40: ='Tab 12 TO1 CLIN X004'!I19 -> 0 | E40: 12 Months
B41: 2004 | C41: Option Year 2 - Lseg Sensor | D41: ='Tab 12 TO1 CLIN X004'!I27 -> 0 | E41: 12 Months
B42: 3004 | C42: Option Year 3 - Lseg Sensor | D42: ='Tab 12 TO1 CLIN X004'!I35 -> 0 | E42: 12 Months
B43: 4004 | C43: Option Year 4 - Lseg Sensor | D43: ='Tab 12 TO1 CLIN X004'!I43 -> 0 | E43: 12 Months
B45: 0005 | C45: Base Period - Nseg Sensor | D45: ='Tab 13 TO1 CLIN X005'!I11 -> 0 | E45: 9 Months | F45: CLIN X005
B46: 1005 | C46: Option Year 1 - Nseg Sensor | D46: ='Tab 13 TO1 CLIN X005'!I19 -> 0 | E46: 12 Months
B48: 0010AA | C48: Base Period ODC - Material Software | D48: 29999 | E48: 12 Months | F48: CLIN X010 Government Provided Estimates - Do Not Alter. Estimates shall be included in the Task Order 0001 Total Price
B49: 1010AA | C49: Option Year 1 - ODC - Material Software | D49: 30598.98 | E49: 12 Months
B50: 2010AA | C50: Option Year 2 - ODC - Material Software | D50: 31210.96 | E50: 12 Months
...
